Workbook

Sheet pengujian
A1: idpengujian | B1: tgluji | C1: idalat | D1: kodebendauji | E1: nodocket | F1: nourutbenda | G1: nilaikn | H1: beratbenda | I1: tiperetak | J1: sinkron | K1: idbendauji | L1: tglrencanauji | M1: bujnama | N1: kuattekan | O1: bebanmpa | P1: umur | Q1: tglbendauji
A2: 10292 | B2: =ODOO!H2 | C2: 4 | D2: =ODOO!P2 | E2: =ODOO!A2 | F2: =ODOO!G2 | G2: =ROUND( IF(AND(P2="7", OR(ODOO!F2="Class B-1 FA", ODOO!F2="Class B-1 NFA")), RAND()*(480-420)+420, IF(AND(P2="28", OR(ODOO!F2="Class B-1 FA", ODOO!F2="Class B-1 NFA")), RAND()*(650-580)+580, IF(AND(P2="7", ODOO!F2="Fc-30 NFA"), RAND()*(480-420)+420, IF(AND(P2="28", ODOO!F2="Fc-30 NFA"), RAND()*(650-580)+580, IF(AND(P2="7", ODOO!F2="Fc-20 NFA"), RAND()*(275-236)+236, IF(AND(P2="28", ODOO!F2="Fc-20 NFA"), RAND()*(490-410)+410, IF(AND(P2="7", ODOO!F2="Fc-35 NFA"), RAND()*(435-393)+393, IF(AND(P2="28", ODOO!F2="Fc-35 NFA"), RAND()*(680-620)+620, IF(AND(P2="7", ODOO!F2="Fc-15 NFA"), RAND()*(200-175)+175, IF(AND(P2="28", ODOO!F2="Fc-15 NFA"), RAND()*(355-305)+305, IF(AND(P2="7", ODOO!F2="K-300 NFA"), RAND()*(324-278)+278, IF(AND(P2="28", ODOO!F2="K-300 NFA"), RAND()*(520-450)+450, IF(AND(P2="7", ODOO!F2="K-300 FA"), RAND()*(324-278)+278, IF(AND(P2="28", ODOO!F2="K-300 FA"), RAND()*(520-450)+450, IF(AND(P2="7", ODOO!F2="K-400 FA"), RAND()*(415-370)+370, IF(AND(P2="28", ODOO!F2="K-400 FA"), RAND()*(655-591)+591, IF(AND(P2="7", ODOO!F2="K-400 NFA"), RAND()*(415-370)+370, IF(AND(P2="28", ODOO!F2="K-400 NFA"), RAND()*(655-591)+591, IF(AND(P2="7", ODOO!F2="Class B-2 FA"), RAND()*(503-448)+448, IF(AND(P2="28", ODOO!F2="Class B-2 FA"), RAND()*(695-622)+622, IF(AND(P2="7", ODOO!F2="Fc-10 NFA"), RAND()*(155-123)+123, IF(AND(P2="28", ODOO!F2="Fc-10 NFA"), RAND()*(230-200)+200, IF(AND(P2="7", ODOO!F2="Class E-1 NFA"), RAND()*(155-123)+123, IF(AND(P2="28", ODOO!F2="Class E-1 NFA"), RAND()*(230-200)+200, IF(AND(P2="7", ODOO!F2="Class E-1 FA"), RAND()*(155-123)+123, IF(AND(P2="28", ODOO!F2="Class E-1 FA"), RAND()*(230-200)+200, IF(AND(P2="7", ODOO!F2="K-175 NFA"), RAND()*(195-165)+165, IF(AND(P2="28", ODOO!F2="K-175 NFA"), RAND()*(320-270)+270, IF(AND(P2="7", ODOO!F2="K-125 NFA"), RAND()*(155-123)+123, IF(AND(P2="28", ODOO!F2="K-125 NFA"), RAND()*(230-200)+200, IF(AND(P2="7", ODOO!F2="B0-1 NFA"), RAND()*(155-123)+123, IF(AND(P2="28", ODOO!F2="B0-1 NFA"), RAND()*(190-177)+177, IF(AND(P2="7", ODOO!F2="Class C-1 NFA"), RAND()*(275-245)+245, IF(AND(P2="28", ODOO!F2="Class C-1 NFA"), RAND()*(460-407)+407, IF(AND(P2="7", ODOO!F2="K-100 NFA"), RAND()*(115-93)+93, IF(AND(P2="28", ODOO!F2="K-100 NFA"), RAND()*(200-146)+146, IF(AND(P2="7", ODOO!F2="K-100 FA"), RAND()*(115-93)+93, IF(AND(P2="28", ODOO!F2="K-100 FA"), RAND()*(200-146)+146, IF(AND(P2="7", ODOO!F2="K-150 NFA"), RAND()*(150-138)+138, IF(AND(P2="28", ODOO!F2="K-150 NFA"), RAND()*(265-220)+220, IF(AND(P2="7", ODOO!F2="K-150 FA"), RAND()*(150-138)+138, IF(AND(P2="28", ODOO!F2="K-150 FA"), RAND()*(265-220)+220, IF(AND(P2="7", ODOO!F2="K-225 NFA"), RAND()*(240-213)+213, IF(AND(P2="28", ODOO!F2="K-225 NFA"), RAND()*(390-348)+348, IF(AND(P2="7", ODOO!F2="K-225 FA"), RAND()*(240-213)+213, IF(AND(P2="28", ODOO!F2="K-225 FA"), RAND()*(390-348)+348, IF(AND(P2="7", ODOO!F2="K-250 NFA"), RAND()*(275-235)+235, IF(AND(P2="28", ODOO!F2="K-250 NFA"), RAND()*(440-400)+400, IF(AND(P2="7", ODOO!F2="K-250 FA"), RAND()*(275-235)+235, IF(AND(P2="28", ODOO!F2="K-250 FA"), RAND()*(440-400)+400, IF(AND(P2="7", ODOO!F2="K-350 NFA"), RAND()*(390-345)+345, IF(AND(P2="28", ODOO!F2="K-350 NFA"), RAND()*(570-520)+520, IF(AND(P2="7", ODOO!F2="K-350 FA"), RAND()*(390-345)+345, IF(AND(P2="28", ODOO!F2="K-350 FA"), RAND()*(570-520)+520, IF(AND(P2="7", ODOO!F2="K-450 FA"), RAND()*(480-420)+420, IF(AND(P2="28", ODOO!F2="K-450 FA"), RAND()*(730-648)+648, IF(AND(P2="7", ODOO!F2="K-450 NFA"), RAND()*(480-420)+420, IF(AND(P2="28", ODOO!F2="K-450 NFA"), RAND()*(730-648)+648, IF(AND(P2="7", ODOO!F2="K-500 FA"), RAND()*(530-466)+466, IF(AND(P2="28", ODOO!F2="K-500 FA"), RAND()*(800-718)+718, IF(AND(P2="7", ODOO!F2="K-500 NFA"), RAND()*(530-466)+466, IF(AND(P2="28", ODOO!F2="K-500 NFA"), RAND()*(800-718)+718, "0")))))))))))))))))))))))))))))))))))))))))))))))))))))))))))))), 2) | H2: =ROUND(RAND()*(12.56-12)+12.1,2) | I2: =CHOOSE(RANDBETWEEN(1,5), "A", "B", "C", "D", "E") | J2: B | K2: =bjdt_id!C2 | L2: =ODOO!H2 | M2: =ODOO!J2 | N2: =ROUND(G2*101.971/176.71/0.83,2) | O2: =ROUND(G2/17671*1000.2,2) | P2: =ODOO!I2 | Q2: =ODOO!H2
A3: =A2+1 | B3: =ODOO!H3 | C3: 4 | D3: =ODOO!P3 | E3: =ODOO!A3 | F3: =ODOO!G3 | G3: =ROUND( IF(AND(P3="7", OR(ODOO!F3="Class B-1 FA", ODOO!F3="Class B-1 NFA")), RAND()*(480-420)+420, IF(AND(P3="28", OR(ODOO!F3="Class B-1 FA", ODOO!F3="Class B-1 NFA")), RAND()*(650-580)+580, IF(AND(P3="7", ODOO!F3="Fc-30 NFA"), RAND()*(480-420)+420, IF(AND(P3="28", ODOO!F3="Fc-30 NFA"), RAND()*(650-580)+580, IF(AND(P3="7", ODOO!F3="Fc-20 NFA"), RAND()*(275-236)+236, IF(AND(P3="28", ODOO!F3="Fc-20 NFA"), RAND()*(490-410)+410, IF(AND(P3="7", ODOO!F3="Fc-35 NFA"), RAND()*(435-393)+393, IF(AND(P3="28", ODOO!F3="Fc-35 NFA"), RAND()*(680-620)+620, IF(AND(P3="7", ODOO!F3="Fc-15 NFA"), RAND()*(200-175)+175, IF(AND(P3="28", ODOO!F3="Fc-15 NFA"), RAND()*(355-305)+305, IF(AND(P3="7", ODOO!F3="K-300 NFA"), RAND()*(324-278)+278, IF(AND(P3="28", ODOO!F3="K-300 NFA"), RAND()*(520-450)+450, IF(AND(P3="7", ODOO!F3="K-300 FA"), RAND()*(324-278)+278, IF(AND(P3="28", ODOO!F3="K-300 FA"), RAND()*(520-450)+450, IF(AND(P3="7", ODOO!F3="K-400 FA"), RAND()*(415-370)+370, IF(AND(P3="28", ODOO!F3="K-400 FA"), RAND()*(655-591)+591, IF(AND(P3="7", ODOO!F3="K-400 NFA"), RAND()*(415-370)+370, IF(AND(P3="28", ODOO!F3="K-400 NFA"), RAND()*(655-591)+591, IF(AND(P3="7", ODOO!F3="Class B-2 FA"), RAND()*(503-448)+448, IF(AND(P3="28", ODOO!F3="Class B-2 FA"), RAND()*(695-622)+622, IF(AND(P3="7", ODOO!F3="Fc-10 NFA"), RAND()*(155-123)+123, IF(AND(P3="28", ODOO!F3="Fc-10 NFA"), RAND()*(230-200)+200, IF(AND(P3="7", ODOO!F3="Class E-1 NFA"), RAND()*(155-123)+123, IF(AND(P3="28", ODOO!F3="Class E-1 NFA"), RAND()*(230-200)+200, IF(AND(P3="7", ODOO!F3="Class E-1 FA"), RAND()*(155-123)+123, IF(AND(P3="28", ODOO!F3="Class E-1 FA"), RAND()*(230-200)+200, IF(AND(P3="7", ODOO!F3="K-175 NFA"), RAND()*(195-165)+165, IF(AND(P3="28", ODOO!F3="K-175 NFA"), RAND()*(320-270)+270, IF(AND(P3="7", ODOO!F3="K-125 NFA"), RAND()*(155-123)+123, IF(AND(P3="28", ODOO!F3="K-125 NFA"), RAND()*(230-200)+200, IF(AND(P3="7", ODOO!F3="B0-1 NFA"), RAND()*(155-123)+123, IF(AND(P3="28", ODOO!F3="B0-1 NFA"), RAND()*(190-177)+177, IF(AND(P3="7", ODOO!F3="Class C-1 NFA"), RAND()*(275-245)+245, IF(AND(P3="28", ODOO!F3="Class C-1 NFA"), RAND()*(460-407)+407, IF(AND(P3="7", ODOO!F3="K-100 NFA"), RAND()*(115-93)+93, IF(AND(P3="28", ODOO!F3="K-100 NFA"), RAND()*(200-146)+146, IF(AND(P3="7", ODOO!F3="K-100 FA"), RAND()*(115-93)+93, IF(AND(P3="28", ODOO!F3="K-100 FA"), RAND()*(200-146)+146, IF(AND(P3="7", ODOO!F3="K-150 NFA"), RAND()*(150-138)+138, IF(AND(P3="28", ODOO!F3="K-150 NFA"), RAND()*(265-220)+220, IF(AND(P3="7", ODOO!F3="K-150 FA"), RAND()*(150-138)+138, IF(AND(P3="28", ODOO!F3="K-150 FA"), RAND()*(265-220)+220, IF(AND(P3="7", ODOO!F3="K-225 NFA"), RAND()*(240-213)+213, IF(AND(P3="28", ODOO!F3="K-225 NFA"), RAND()*(390-348)+348, IF(AND(P3="7", ODOO!F3="K-225 FA"), RAND()*(240-213)+213, IF(AND(P3="28", ODOO!F3="K-225 FA"), RAND()*(390-348)+348, IF(AND(P3="7", ODOO!F3="K-250 NFA"), RAND()*(275-235)+235, IF(AND(P3="28", ODOO!F3="K-250 NFA"), RAND()*(440-400)+400, IF(AND(P3="7", ODOO!F3="K-250 FA"), RAND()*(275-235)+235, IF(AND(P3="28", ODOO!F3="K-250 FA"), RAND()*(440-400)+400, IF(AND(P3="7", ODOO!F3="K-350 NFA"), RAND()*(390-345)+345, IF(AND(P3="28", ODOO!F3="K-350 NFA"), RAND()*(570-520)+520, IF(AND(P3="7", ODOO!F3="K-350 FA"), RAND()*(390-345)+345, IF(AND(P3="28", ODOO!F3="K-350 FA"), RAND()*(570-520)+520, IF(AND(P3="7", ODOO!F3="K-450 FA"), RAND()*(480-420)+420, IF(AND(P3="28", ODOO!F3="K-450 FA"), RAND()*(730-648)+648, IF(AND(P3="7", ODOO!F3="K-450 NFA"), RAND()*(480-420)+420, IF(AND(P3="28", ODOO!F3="K-450 NFA"), RAND()*(730-648)+648, IF(AND(P3="7", ODOO!F3="K-500 FA"), RAND()*(530-466)+466, IF(AND(P3="28", ODOO!F3="K-500 FA"), RAND()*(800-718)+718, IF(AND(P3="7", ODOO!F3="K-500 NFA"), RAND()*(530-466)+466, IF(AND(P3="28", ODOO!F3="K-500 NFA"), RAND()*(800-718)+718, "0")))))))))))))))))))))))))))))))))))))))))))))))))))))))))))))), 2) | H3: =ROUND(RAND()*(12.56-12)+12.1,2) | I3: =CHOOSE(RANDBETWEEN(1,5), "A", "B", "C", "D", "E") | J3: B | K3: =bjdt_id!C3 | L3: =ODOO!H3 | M3: =ODOO!J3 | N3: =ROUND(G3*101.971/176.71/0.83,2) | O3: =ROUND(G3/17671*1000.2,2) | P3: =ODOO!I3 | Q3: =ODOO!H3
A4: =A3+1 | B4: =ODOO!H4 | C4: 4 | D4: =ODOO!P4 | E4: =ODOO!A4 | F4: =ODOO!G4 | G4: =ROUND( IF(AND(P4="7", OR(ODOO!F4="Class B-1 FA", ODOO!F4="Class B-1 NFA")), RAND()*(480-420)+420, IF(AND(P4="28", OR(ODOO!F4="Class B-1 FA", ODOO!F4="Class B-1 NFA")), RAND()*(650-580)+580, IF(AND(P4="7", ODOO!F4="Fc-30 NFA"), RAND()*(480-420)+420, IF(AND(P4="28", ODOO!F4="Fc-30 NFA"), RAND()*(650-580)+580, IF(AND(P4="7", ODOO!F4="Fc-20 NFA"), RAND()*(275-236)+236, IF(AND(P4="28", ODOO!F4="Fc-20 NFA"), RAND()*(490-410)+410, IF(AND(P4="7", ODOO!F4="Fc-35 NFA"), RAND()*(435-393)+393, IF(AND(P4="28", ODOO!F4="Fc-35 NFA"), RAND()*(680-620)+620, IF(AND(P4="7", ODOO!F4="Fc-15 NFA"), RAND()*(200-175)+175, IF(AND(P4="28", ODOO!F4="Fc-15 NFA"), RAND()*(355-305)+305, IF(AND(P4="7", ODOO!F4="K-300 NFA"), RAND()*(324-278)+278, IF(AND(P4="28", ODOO!F4="K-300 NFA"), RAND()*(520-450)+450, IF(AND(P4="7", ODOO!F4="K-300 FA"), RAND()*(324-278)+278, IF(AND(P4="28", ODOO!F4="K-300 FA"), RAND()*(520-450)+450, IF(AND(P4="7", ODOO!F4="K-400 FA"), RAND()*(415-370)+370, IF(AND(P4="28", ODOO!F4="K-400 FA"), RAND()*(655-591)+591, IF(AND(P4="7", ODOO!F4="K-400 NFA"), RAND()*(415-370)+370, IF(AND(P4="28", ODOO!F4="K-400 NFA"), RAND()*(655-591)+591, IF(AND(P4="7", ODOO!F4="Class B-2 FA"), RAND()*(503-448)+448, IF(AND(P4="28", ODOO!F4="Class B-2 FA"), RAND()*(695-622)+622, IF(AND(P4="7", ODOO!F4="Fc-10 NFA"), RAND()*(155-123)+123, IF(AND(P4="28", ODOO!F4="Fc-10 NFA"), RAND()*(230-200)+200, IF(AND(P4="7", ODOO!F4="Class E-1 NFA"), RAND()*(155-123)+123, IF(AND(P4="28", ODOO!F4="Class E-1 NFA"), RAND()*(230-200)+200, IF(AND(P4="7", ODOO!F4="Class E-1 FA"), RAND()*(155-123)+123, IF(AND(P4="28", ODOO!F4="Class E-1 FA"), RAND()*(230-200)+200, IF(AND(P4="7", ODOO!F4="K-175 NFA"), RAND()*(195-165)+165, IF(AND(P4="28", ODOO!F4="K-175 NFA"), RAND()*(320-270)+270, IF(AND(P4="7", ODOO!F4="K-125 NFA"), RAND()*(155-123)+123, IF(AND(P4="28", ODOO!F4="K-125 NFA"), RAND()*(230-200)+200, IF(AND(P4="7", ODOO!F4="B0-1 NFA"), RAND()*(155-123)+123, IF(AND(P4="28", ODOO!F4="B0-1 NFA"), RAND()*(190-177)+177, IF(AND(P4="7", ODOO!F4="Class C-1 NFA"), RAND()*(275-245)+245, IF(AND(P4="28", ODOO!F4="Class C-1 NFA"), RAND()*(460-407)+407, IF(AND(P4="7", ODOO!F4="K-100 NFA"), RAND()*(115-93)+93, IF(AND(P4="28", ODOO!F4="K-100 NFA"), RAND()*(200-146)+146, IF(AND(P4="7", ODOO!F4="K-100 FA"), RAND()*(115-93)+93, IF(AND(P4="28", ODOO!F4="K-100 FA"), RAND()*(200-146)+146, IF(AND(P4="7", ODOO!F4="K-150 NFA"), RAND()*(150-138)+138, IF(AND(P4="28", ODOO!F4="K-150 NFA"), RAND()*(265-220)+220, IF(AND(P4="7", ODOO!F4="K-150 FA"), RAND()*(150-138)+138, IF(AND(P4="28", ODOO!F4="K-150 FA"), RAND()*(265-220)+220, IF(AND(P4="7", ODOO!F4="K-225 NFA"), RAND()*(240-213)+213, IF(AND(P4="28", ODOO!F4="K-225 NFA"), RAND()*(390-348)+348, IF(AND(P4="7", ODOO!F4="K-225 FA"), RAND()*(240-213)+213, IF(AND(P4="28", ODOO!F4="K-225 FA"), RAND()*(390-348)+348, IF(AND(P4="7", ODOO!F4="K-250 NFA"), RAND()*(275-235)+235, IF(AND(P4="28", ODOO!F4="K-250 NFA"), RAND()*(440-400)+400, IF(AND(P4="7", ODOO!F4="K-250 FA"), RAND()*(275-235)+235, IF(AND(P4="28", ODOO!F4="K-250 FA"), RAND()*(440-400)+400, IF(AND(P4="7", ODOO!F4="K-350 NFA"), RAND()*(390-345)+345, IF(AND(P4="28", ODOO!F4="K-350 NFA"), RAND()*(570-520)+520, IF(AND(P4="7", ODOO!F4="K-350 FA"), RAND()*(390-345)+345, IF(AND(P4="28", ODOO!F4="K-350 FA"), RAND()*(570-520)+520, IF(AND(P4="7", ODOO!F4="K-450 FA"), RAND()*(480-420)+420, IF(AND(P4="28", ODOO!F4="K-450 FA"), RAND()*(730-648)+648, IF(AND(P4="7", ODOO!F4="K-450 NFA"), RAND()*(480-420)+420, IF(AND(P4="28", ODOO!F4="K-450 NFA"), RAND()*(730-648)+648, IF(AND(P4="7", ODOO!F4="K-500 FA"), RAND()*(530-466)+466, IF(AND(P4="28", ODOO!F4="K-500 FA"), RAND()*(800-718)+718, IF(AND(P4="7", ODOO!F4="K-500 NFA"), RAND()*(530-466)+466, IF(AND(P4="28", ODOO!F4="K-500 NFA"), RAND()*(800-718)+718, "0")))))))))))))))))))))))))))))))))))))))))))))))))))))))))))))), 2) | H4: =ROUND(RAND()*(12.56-12)+12.1,2) | I4: =CHOOSE(RANDBETWEEN(1,5), "A", "B", "C", "D", "E") | J4: B | K4: =bjdt_id!C4 | L4: =ODOO!H4 | M4: =ODOO!J4 | N4: =ROUND(G4*101.971/176.71/0.83,2) | O4: =ROUND(G4/17671*1000.2,2) | P4: =ODOO!I4 | Q4: =ODOO!H4
A5: =A4+1 | B5: =ODOO!H5 | C5: 4 | D5: =ODOO!P5 | E5: =ODOO!A5 | F5: =ODOO!G5 | G5: =ROUND( IF(AND(P5="7", OR(ODOO!F5="Class B-1 FA", ODOO!F5="Class B-1 NFA")), RAND()*(480-420)+420, IF(AND(P5="28", OR(ODOO!F5="Class B-1 FA", ODOO!F5="Class B-1 NFA")), RAND()*(650-580)+580, IF(AND(P5="7", ODOO!F5="Fc-30 NFA"), RAND()*(480-420)+420, IF(AND(P5="28", ODOO!F5="Fc-30 NFA"), RAND()*(650-580)+580, IF(AND(P5="7", ODOO!F5="Fc-20 NFA"), RAND()*(275-236)+236, IF(AND(P5="28", ODOO!F5="Fc-20 NFA"), RAND()*(490-410)+410, IF(AND(P5="7", ODOO!F5="Fc-35 NFA"), RAND()*(435-393)+393, IF(AND(P5="28", ODOO!F5="Fc-35 NFA"), RAND()*(680-620)+620, IF(AND(P5="7", ODOO!F5="Fc-15 NFA"), RAND()*(200-175)+175, IF(AND(P5="28", ODOO!F5="Fc-15 NFA"), RAND()*(355-305)+305, IF(AND(P5="7", ODOO!F5="K-300 NFA"), RAND()*(324-278)+278, IF(AND(P5="28", ODOO!F5="K-300 NFA"), RAND()*(520-450)+450, IF(AND(P5="7", ODOO!F5="K-300 FA"), RAND()*(324-278)+278, IF(AND(P5="28", ODOO!F5="K-300 FA"), RAND()*(520-450)+450, IF(AND(P5="7", ODOO!F5="K-400 FA"), RAND()*(415-370)+370, IF(AND(P5="28", ODOO!F5="K-400 FA"), RAND()*(655-591)+591, IF(AND(P5="7", ODOO!F5="K-400 NFA"), RAND()*(415-370)+370, IF(AND(P5="28", ODOO!F5="K-400 NFA"), RAND()*(655-591)+591, IF(AND(P5="7", ODOO!F5="Class B-2 FA"), RAND()*(503-448)+448, IF(AND(P5="28", ODOO!F5="Class B-2 FA"), RAND()*(695-622)+622, IF(AND(P5="7", ODOO!F5="Fc-10 NFA"), RAND()*(155-123)+123, IF(AND(P5="28", ODOO!F5="Fc-10 NFA"), RAND()*(230-200)+200, IF(AND(P5="7", ODOO!F5="Class E-1 NFA"), RAND()*(155-123)+123, IF(AND(P5="28", ODOO!F5="Class E-1 NFA"), RAND()*(230-200)+200, IF(AND(P5="7", ODOO!F5="Class E-1 FA"), RAND()*(155-123)+123, IF(AND(P5="28", ODOO!F5="Class E-1 FA"), RAND()*(230-200)+200, IF(AND(P5="7", ODOO!F5="K-175 NFA"), RAND()*(195-165)+165, IF(AND(P5="28", ODOO!F5="K-175 NFA"), RAND()*(320-270)+270, IF(AND(P5="7", ODOO!F5="K-125 NFA"), RAND()*(155-123)+123, IF(AND(P5="28", ODOO!F5="K-125 NFA"), RAND()*(230-200)+200, IF(AND(P5="7", ODOO!F5="B0-1 NFA"), RAND()*(155-123)+123, IF(AND(P5="28", ODOO!F5="B0-1 NFA"), RAND()*(190-177)+177, IF(AND(P5="7", ODOO!F5="Class C-1 NFA"), RAND()*(275-245)+245, IF(AND(P5="28", ODOO!F5="Class C-1 NFA"), RAND()*(460-407)+407, IF(AND(P5="7", ODOO!F5="K-100 NFA"), RAND()*(115-93)+93, IF(AND(P5="28", ODOO!F5="K-100 NFA"), RAND()*(200-146)+146, IF(AND(P5="7", ODOO!F5="K-100 FA"), RAND()*(115-93)+93, IF(AND(P5="28", ODOO!F5="K-100 FA"), RAND()*(200-146)+146, IF(AND(P5="7", ODOO!F5="K-150 NFA"), RAND()*(150-138)+138, IF(AND(P5="28", ODOO!F5="K-150 NFA"), RAND()*(265-220)+220, IF(AND(P5="7", ODOO!F5="K-150 FA"), RAND()*(150-138)+138, IF(AND(P5="28", ODOO!F5="K-150 FA"), RAND()*(265-220)+220, IF(AND(P5="7", ODOO!F5="K-225 NFA"), RAND()*(240-213)+213, IF(AND(P5="28", ODOO!F5="K-225 NFA"), RAND()*(390-348)+348, IF(AND(P5="7", ODOO!F5="K-225 FA"), RAND()*(240-213)+213, IF(AND(P5="28", ODOO!F5="K-225 FA"), RAND()*(390-348)+348, IF(AND(P5="7", ODOO!F5="K-250 NFA"), RAND()*(275-235)+235, IF(AND(P5="28", ODOO!F5="K-250 NFA"), RAND()*(440-400)+400, IF(AND(P5="7", ODOO!F5="K-250 FA"), RAND()*(275-235)+235, IF(AND(P5="28", ODOO!F5="K-250 FA"), RAND()*(440-400)+400, IF(AND(P5="7", ODOO!F5="K-350 NFA"), RAND()*(390-345)+345, IF(AND(P5="28", ODOO!F5="K-350 NFA"), RAND()*(570-520)+520, IF(AND(P5="7", ODOO!F5="K-350 FA"), RAND()*(390-345)+345, IF(AND(P5="28", ODOO!F5="K-350 FA"), RAND()*(570-520)+520, IF(AND(P5="7", ODOO!F5="K-450 FA"), RAND()*(480-420)+420, IF(AND(P5="28", ODOO!F5="K-450 FA"), RAND()*(730-648)+648, IF(AND(P5="7", ODOO!F5="K-450 NFA"), RAND()*(480-420)+420, IF(AND(P5="28", ODOO!F5="K-450 NFA"), RAND()*(730-648)+648, IF(AND(P5="7", ODOO!F5="K-500 FA"), RAND()*(530-466)+466, IF(AND(P5="28", ODOO!F5="K-500 FA"), RAND()*(800-718)+718, IF(AND(P5="7", ODOO!F5="K-500 NFA"), RAND()*(530-466)+466, IF(AND(P5="28", ODOO!F5="K-500 NFA"), RAND()*(800-718)+718, "0")))))))))))))))))))))))))))))))))))))))))))))))))))))))))))))), 2) | H5: =ROUND(RAND()*(12.56-12)+12.1,2) | I5: =CHOOSE(RANDBETWEEN(1,5), "A", "B", "C", "D", "E") | J5: B | K5: =bjdt_id!C5 | L5: =ODOO!H5 | M5: =ODOO!J5 | N5: =ROUND(G5*101.971/176.71/0.83,2) | O5: =ROUND(G5/17671*1000.2,2) | P5: =ODOO!I5 | Q5: =ODOO!H5
A6: =A5+1 | B6: =ODOO!H6 | C6: 4 | D6: =ODOO!P6 | E6: =ODOO!A6 | F6: =ODOO!G6 | G6: =ROUND( IF(AND(P6="7", OR(ODOO!F6="Class B-1 FA", ODOO!F6="Class B-1 NFA")), RAND()*(480-420)+420, IF(AND(P6="28", OR(ODOO!F6="Class B-1 FA", ODOO!F6="Class B-1 NFA")), RAND()*(650-580)+580, IF(AND(P6="7", ODOO!F6="Fc-30 NFA"), RAND()*(480-420)+420, IF(AND(P6="28", ODOO!F6="Fc-30 NFA"), RAND()*(650-580)+580, IF(AND(P6="7", ODOO!F6="Fc-20 NFA"), RAND()*(275-236)+236, IF(AND(P6="28", ODOO!F6="Fc-20 NFA"), RAND()*(490-410)+410, IF(AND(P6="7", ODOO!F6="Fc-35 NFA"), RAND()*(435-393)+393, IF(AND(P6="28", ODOO!F6="Fc-35 NFA"), RAND()*(680-620)+620, IF(AND(P6="7", ODOO!F6="Fc-15 NFA"), RAND()*(200-175)+175, IF(AND(P6="28", ODOO!F6="Fc-15 NFA"), RAND()*(355-305)+305, IF(AND(P6="7", ODOO!F6="K-300 NFA"), RAND()*(324-278)+278, IF(AND(P6="28", ODOO!F6="K-300 NFA"), RAND()*(520-450)+450, IF(AND(P6="7", ODOO!F6="K-300 FA"), RAND()*(324-278)+278, IF(AND(P6="28", ODOO!F6="K-300 FA"), RAND()*(520-450)+450, IF(AND(P6="7", ODOO!F6="K-400 FA"), RAND()*(415-370)+370, IF(AND(P6="28", ODOO!F6="K-400 FA"), RAND()*(655-591)+591, IF(AND(P6="7", ODOO!F6="K-400 NFA"), RAND()*(415-370)+370, IF(AND(P6="28", ODOO!F6="K-400 NFA"), RAND()*(655-591)+591, IF(AND(P6="7", ODOO!F6="Class B-2 FA"), RAND()*(503-448)+448, IF(AND(P6="28", ODOO!F6="Class B-2 FA"), RAND()*(695-622)+622, IF(AND(P6="7", ODOO!F6="Fc-10 NFA"), RAND()*(155-123)+123, IF(AND(P6="28", ODOO!F6="Fc-10 NFA"), RAND()*(230-200)+200, IF(AND(P6="7", ODOO!F6="Class E-1 NFA"), RAND()*(155-123)+123, IF(AND(P6="28", ODOO!F6="Class E-1 NFA"), RAND()*(230-200)+200, IF(AND(P6="7", ODOO!F6="Class E-1 FA"), RAND()*(155-123)+123, IF(AND(P6="28", ODOO!F6="Class E-1 FA"), RAND()*(230-200)+200, IF(AND(P6="7", ODOO!F6="K-175 NFA"), RAND()*(195-165)+165, IF(AND(P6="28", ODOO!F6="K-175 NFA"), RAND()*(320-270)+270, IF(AND(P6="7", ODOO!F6="K-125 NFA"), RAND()*(155-123)+123, IF(AND(P6="28", ODOO!F6="K-125 NFA"), RAND()*(230-200)+200, IF(AND(P6="7", ODOO!F6="B0-1 NFA"), RAND()*(155-123)+123, IF(AND(P6="28", ODOO!F6="B0-1 NFA"), RAND()*(190-177)+177, IF(AND(P6="7", ODOO!F6="Class C-1 NFA"), RAND()*(275-245)+245, IF(AND(P6="28", ODOO!F6="Class C-1 NFA"), RAND()*(460-407)+407, IF(AND(P6="7", ODOO!F6="K-100 NFA"), RAND()*(115-93)+93, IF(AND(P6="28", ODOO!F6="K-100 NFA"), RAND()*(200-146)+146, IF(AND(P6="7", ODOO!F6="K-100 FA"), RAND()*(115-93)+93, IF(AND(P6="28", ODOO!F6="K-100 FA"), RAND()*(200-146)+146, IF(AND(P6="7", ODOO!F6="K-150 NFA"), RAND()*(150-138)+138, IF(AND(P6="28", ODOO!F6="K-150 NFA"), RAND()*(265-220)+220, IF(AND(P6="7", ODOO!F6="K-150 FA"), RAND()*(150-138)+138, IF(AND(P6="28", ODOO!F6="K-150 FA"), RAND()*(265-220)+220, IF(AND(P6="7", ODOO!F6="K-225 NFA"), RAND()*(240-213)+213, IF(AND(P6="28", ODOO!F6="K-225 NFA"), RAND()*(390-348)+348, IF(AND(P6="7", ODOO!F6="K-225 FA"), RAND()*(240-213)+213, IF(AND(P6="28", ODOO!F6="K-225 FA"), RAND()*(390-348)+348, IF(AND(P6="7", ODOO!F6="K-250 NFA"), RAND()*(275-235)+235, IF(AND(P6="28", ODOO!F6="K-250 NFA"), RAND()*(440-400)+400, IF(AND(P6="7", ODOO!F6="K-250 FA"), RAND()*(275-235)+235, IF(AND(P6="28", ODOO!F6="K-250 FA"), RAND()*(440-400)+400, IF(AND(P6="7", ODOO!F6="K-350 NFA"), RAND()*(390-345)+345, IF(AND(P6="28", ODOO!F6="K-350 NFA"), RAND()*(570-520)+520, IF(AND(P6="7", ODOO!F6="K-350 FA"), RAND()*(390-345)+345, IF(AND(P6="28", ODOO!F6="K-350 FA"), RAND()*(570-520)+520, IF(AND(P6="7", ODOO!F6="K-450 FA"), RAND()*(480-420)+420, IF(AND(P6="28", ODOO!F6="K-450 FA"), RAND()*(730-648)+648, IF(AND(P6="7", ODOO!F6="K-450 NFA"), RAND()*(480-420)+420, IF(AND(P6="28", ODOO!F6="K-450 NFA"), RAND()*(730-648)+648, IF(AND(P6="7", ODOO!F6="K-500 FA"), RAND()*(530-466)+466, IF(AND(P6="28", ODOO!F6="K-500 FA"), RAND()*(800-718)+718, IF(AND(P6="7", ODOO!F6="K-500 NFA"), RAND()*(530-466)+466, IF(AND(P6="28", ODOO!F6="K-500 NFA"), RAND()*(800-718)+718, "0")))))))))))))))))))))))))))))))))))))))))))))))))))))))))))))), 2) | H6: =ROUND(RAND()*(12.56-12)+12.1,2) | I6: =CHOOSE(RANDBETWEEN(1,5), "A", "B", "C", "D", "E") | J6: B | K6: =bjdt_id!C6 | L6: =ODOO!H6 | M6: =ODOO!J6 | N6: =ROUND(G6*101.971/176.71/0.83,2) | O6: =ROUND(G6/17671*1000.2,2) | P6: =ODOO!I6 | Q6: =ODOO!H6
A7: =A6+1 | B7: =ODOO!H7 | C7: 4 | D7: =ODOO!P7 | E7: =ODOO!A7 | F7: =ODOO!G7 | G7: =ROUND( IF(AND(P7="7", OR(ODOO!F7="Class B-1 FA", ODOO!F7="Class B-1 NFA")), RAND()*(480-420)+420, IF(AND(P7="28", OR(ODOO!F7="Class B-1 FA", ODOO!F7="Class B-1 NFA")), RAND()*(650-580)+580, IF(AND(P7="7", ODOO!F7="Fc-30 NFA"), RAND()*(480-420)+420, IF(AND(P7="28", ODOO!F7="Fc-30 NFA"), RAND()*(650-580)+580, IF(AND(P7="7", ODOO!F7="Fc-20 NFA"), RAND()*(275-236)+236, IF(AND(P7="28", ODOO!F7="Fc-20 NFA"), RAND()*(490-410)+410, IF(AND(P7="7", ODOO!F7="Fc-35 NFA"), RAND()*(435-393)+393, IF(AND(P7="28", ODOO!F7="Fc-35 NFA"), RAND()*(680-620)+620, IF(AND(P7="7", ODOO!F7="Fc-15 NFA"), RAND()*(200-175)+175, IF(AND(P7="28", ODOO!F7="Fc-15 NFA"), RAND()*(355-305)+305, IF(AND(P7="7", ODOO!F7="K-300 NFA"), RAND()*(324-278)+278, IF(AND(P7="28", ODOO!F7="K-300 NFA"), RAND()*(520-450)+450, IF(AND(P7="7", ODOO!F7="K-300 FA"), RAND()*(324-278)+278, IF(AND(P7="28", ODOO!F7="K-300 FA"), RAND()*(520-450)+450, IF(AND(P7="7", ODOO!F7="K-400 FA"), RAND()*(415-370)+370, IF(AND(P7="28", ODOO!F7="K-400 FA"), RAND()*(655-591)+591, IF(AND(P7="7", ODOO!F7="K-400 NFA"), RAND()*(415-370)+370, IF(AND(P7="28", ODOO!F7="K-400 NFA"), RAND()*(655-591)+591, IF(AND(P7="7", ODOO!F7="Class B-2 FA"), RAND()*(503-448)+448, IF(AND(P7="28", ODOO!F7="Class B-2 FA"), RAND()*(695-622)+622, IF(AND(P7="7", ODOO!F7="Fc-10 NFA"), RAND()*(155-123)+123, IF(AND(P7="28", ODOO!F7="Fc-10 NFA"), RAND()*(230-200)+200, IF(AND(P7="7", ODOO!F7="Class E-1 NFA"), RAND()*(155-123)+123, IF(AND(P7="28", ODOO!F7="Class E-1 NFA"), RAND()*(230-200)+200, IF(AND(P7="7", ODOO!F7="Class E-1 FA"), RAND()*(155-123)+123, IF(AND(P7="28", ODOO!F7="Class E-1 FA"), RAND()*(230-200)+200, IF(AND(P7="7", ODOO!F7="K-175 NFA"), RAND()*(195-165)+165, IF(AND(P7="28", ODOO!F7="K-175 NFA"), RAND()*(320-270)+270, IF(AND(P7="7", ODOO!F7="K-125 NFA"), RAND()*(155-123)+123, IF(AND(P7="28", ODOO!F7="K-125 NFA"), RAND()*(230-200)+200, IF(AND(P7="7", ODOO!F7="B0-1 NFA"), RAND()*(155-123)+123, IF(AND(P7="28", ODOO!F7="B0-1 NFA"), RAND()*(190-177)+177, IF(AND(P7="7", ODOO!F7="Class C-1 NFA"), RAND()*(275-245)+245, IF(AND(P7="28", ODOO!F7="Class C-1 NFA"), RAND()*(460-407)+407, IF(AND(P7="7", ODOO!F7="K-100 NFA"), RAND()*(115-93)+93, IF(AND(P7="28", ODOO!F7="K-100 NFA"), RAND()*(200-146)+146, IF(AND(P7="7", ODOO!F7="K-100 FA"), RAND()*(115-93)+93, IF(AND(P7="28", ODOO!F7="K-100 FA"), RAND()*(200-146)+146, IF(AND(P7="7", ODOO!F7="K-150 NFA"), RAND()*(150-138)+138, IF(AND(P7="28", ODOO!F7="K-150 NFA"), RAND()*(265-220)+220, IF(AND(P7="7", ODOO!F7="K-150 FA"), RAND()*(150-138)+138, IF(AND(P7="28", ODOO!F7="K-150 FA"), RAND()*(265-220)+220, IF(AND(P7="7", ODOO!F7="K-225 NFA"), RAND()*(240-213)+213, IF(AND(P7="28", ODOO!F7="K-225 NFA"), RAND()*(390-348)+348, IF(AND(P7="7", ODOO!F7="K-225 FA"), RAND()*(240-213)+213, IF(AND(P7="28", ODOO!F7="K-225 FA"), RAND()*(390-348)+348, IF(AND(P7="7", ODOO!F7="K-250 NFA"), RAND()*(275-235)+235, IF(AND(P7="28", ODOO!F7="K-250 NFA"), RAND()*(440-400)+400, IF(AND(P7="7", ODOO!F7="K-250 FA"), RAND()*(275-235)+235, IF(AND(P7="28", ODOO!F7="K-250 FA"), RAND()*(440-400)+400, IF(AND(P7="7", ODOO!F7="K-350 NFA"), RAND()*(390-345)+345, IF(AND(P7="28", ODOO!F7="K-350 NFA"), RAND()*(570-520)+520, IF(AND(P7="7", ODOO!F7="K-350 FA"), RAND()*(390-345)+345, IF(AND(P7="28", ODOO!F7="K-350 FA"), RAND()*(570-520)+520, IF(AND(P7="7", ODOO!F7="K-450 FA"), RAND()*(480-420)+420, IF(AND(P7="28", ODOO!F7="K-450 FA"), RAND()*(730-648)+648, IF(AND(P7="7", ODOO!F7="K-450 NFA"), RAND()*(480-420)+420, IF(AND(P7="28", ODOO!F7="K-450 NFA"), RAND()*(730-648)+648, IF(AND(P7="7", ODOO!F7="K-500 FA"), RAND()*(530-466)+466, IF(AND(P7="28", ODOO!F7="K-500 FA"), RAND()*(800-718)+718, IF(AND(P7="7", ODOO!F7="K-500 NFA"), RAND()*(530-466)+466, IF(AND(P7="28", ODOO!F7="K-500 NFA"), RAND()*(800-718)+718, "0")))))))))))))))))))))))))))))))))))))))))))))))))))))))))))))), 2) | H7: =ROUND(RAND()*(12.56-12)+12.1,2) | I7: =CHOOSE(RANDBETWEEN(1,5), "A", "B", "C", "D", "E") | J7: B | K7: =bjdt_id!C7 | L7: =ODOO!H7 | M7: =ODOO!J7 | N7: =ROUND(G7*101.971/176.71/0.83,2) | O7: =ROUND(G7/17671*1000.2,2) | P7: =ODOO!I7 | Q7: =ODOO!H7
A8: =A7+1 | B8: =ODOO!H8 | C8: 4 | D8: =ODOO!P8 | E8: =ODOO!A8 | F8: =ODOO!G8 | G8: =ROUND( IF(AND(P8="7", OR(ODOO!F8="Class B-1 FA", ODOO!F8="Class B-1 NFA")), RAND()*(480-420)+420, IF(AND(P8="28", OR(ODOO!F8="Class B-1 FA", ODOO!F8="Class B-1 NFA")), RAND()*(650-580)+580, IF(AND(P8="7", ODOO!F8="Fc-30 NFA"), RAND()*(480-420)+420, IF(AND(P8="28", ODOO!F8="Fc-30 NFA"), RAND()*(650-580)+580, IF(AND(P8="7", ODOO!F8="Fc-20 NFA"), RAND()*(275-236)+236, IF(AND(P8="28", ODOO!F8="Fc-20 NFA"), RAND()*(490-410)+410, IF(AND(P8="7", ODOO!F8="Fc-35 NFA"), RAND()*(435-393)+393, IF(AND(P8="28", ODOO!F8="Fc-35 NFA"), RAND()*(680-620)+620, IF(AND(P8="7", ODOO!F8="Fc-15 NFA"), RAND()*(200-175)+175, IF(AND(P8="28", ODOO!F8="Fc-15 NFA"), RAND()*(355-305)+305, IF(AND(P8="7", ODOO!F8="K-300 NFA"), RAND()*(324-278)+278, IF(AND(P8="28", ODOO!F8="K-300 NFA"), RAND()*(520-450)+450, IF(AND(P8="7", ODOO!F8="K-300 FA"), RAND()*(324-278)+278, IF(AND(P8="28", ODOO!F8="K-300 FA"), RAND()*(520-450)+450, IF(AND(P8="7", ODOO!F8="K-400 FA"), RAND()*(415-370)+370, IF(AND(P8="28", ODOO!F8="K-400 FA"), RAND()*(655-591)+591, IF(AND(P8="7", ODOO!F8="K-400 NFA"), RAND()*(415-370)+370, IF(AND(P8="28", ODOO!F8="K-400 NFA"), RAND()*(655-591)+591, IF(AND(P8="7", ODOO!F8="Class B-2 FA"), RAND()*(503-448)+448, IF(AND(P8="28", ODOO!F8="Class B-2 FA"), RAND()*(695-622)+622, IF(AND(P8="7", ODOO!F8="Fc-10 NFA"), RAND()*(155-123)+123, IF(AND(P8="28", ODOO!F8="Fc-10 NFA"), RAND()*(230-200)+200, IF(AND(P8="7", ODOO!F8="Class E-1 NFA"), RAND()*(155-123)+123, IF(AND(P8="28", ODOO!F8="Class E-1 NFA"), RAND()*(230-200)+200, IF(AND(P8="7", ODOO!F8="Class E-1 FA"), RAND()*(155-123)+123, IF(AND(P8="28", ODOO!F8="Class E-1 FA"), RAND()*(230-200)+200, IF(AND(P8="7", ODOO!F8="K-175 NFA"), RAND()*(195-165)+165, IF(AND(P8="28", ODOO!F8="K-175 NFA"), RAND()*(320-270)+270, IF(AND(P8="7", ODOO!F8="K-125 NFA"), RAND()*(155-123)+123, IF(AND(P8="28", ODOO!F8="K-125 NFA"), RAND()*(230-200)+200, IF(AND(P8="7", ODOO!F8="B0-1 NFA"), RAND()*(155-123)+123, IF(AND(P8="28", ODOO!F8="B0-1 NFA"), RAND()*(190-177)+177, IF(AND(P8="7", ODOO!F8="Class C-1 NFA"), RAND()*(275-245)+245, IF(AND(P8="28", ODOO!F8="Class C-1 NFA"), RAND()*(460-407)+407, IF(AND(P8="7", ODOO!F8="K-100 NFA"), RAND()*(115-93)+93, IF(AND(P8="28", ODOO!F8="K-100 NFA"), RAND()*(200-146)+146, IF(AND(P8="7", ODOO!F8="K-100 FA"), RAND()*(115-93)+93, IF(AND(P8="28", ODOO!F8="K-100 FA"), RAND()*(200-146)+146, IF(AND(P8="7", ODOO!F8="K-150 NFA"), RAND()*(150-138)+138, IF(AND(P8="28", ODOO!F8="K-150 NFA"), RAND()*(265-220)+220, IF(AND(P8="7", ODOO!F8="K-150 FA"), RAND()*(150-138)+138, IF(AND(P8="28", ODOO!F8="K-150 FA"), RAND()*(265-220)+220, IF(AND(P8="7", ODOO!F8="K-225 NFA"), RAND()*(240-213)+213, IF(AND(P8="28", ODOO!F8="K-225 NFA"), RAND()*(390-348)+348, IF(AND(P8="7", ODOO!F8="K-225 FA"), RAND()*(240-213)+213, IF(AND(P8="28", ODOO!F8="K-225 FA"), RAND()*(390-348)+348, IF(AND(P8="7", ODOO!F8="K-250 NFA"), RAND()*(275-235)+235, IF(AND(P8="28", ODOO!F8="K-250 NFA"), RAND()*(440-400)+400, IF(AND(P8="7", ODOO!F8="K-250 FA"), RAND()*(275-235)+235, IF(AND(P8="28", ODOO!F8="K-250 FA"), RAND()*(440-400)+400, IF(AND(P8="7", ODOO!F8="K-350 NFA"), RAND()*(390-345)+345, IF(AND(P8="28", ODOO!F8="K-350 NFA"), RAND()*(570-520)+520, IF(AND(P8="7", ODOO!F8="K-350 FA"), RAND()*(390-345)+345, IF(AND(P8="28", ODOO!F8="K-350 FA"), RAND()*(570-520)+520, IF(AND(P8="7", ODOO!F8="K-450 FA"), RAND()*(480-420)+420, IF(AND(P8="28", ODOO!F8="K-450 FA"), RAND()*(730-648)+648, IF(AND(P8="7", ODOO!F8="K-450 NFA"), RAND()*(480-420)+420, IF(AND(P8="28", ODOO!F8="K-450 NFA"), RAND()*(730-648)+648, IF(AND(P8="7", ODOO!F8="K-500 FA"), RAND()*(530-466)+466, IF(AND(P8="28", ODOO!F8="K-500 FA"), RAND()*(800-718)+718, IF(AND(P8="7", ODOO!F8="K-500 NFA"), RAND()*(530-466)+466, IF(AND(P8="28", ODOO!F8="K-500 NFA"), RAND()*(800-718)+718, "0")))))))))))))))))))))))))))))))))))))))))))))))))))))))))))))), 2) | H8: =ROUND(RAND()*(12.56-12)+12.1,2) | I8: =CHOOSE(RANDBETWEEN(1,5), "A", "B", "C", "D", "E") | J8: B | K8: =bjdt_id!C8 | L8: =ODOO!H8 | M8: =ODOO!J8 | N8: =ROUND(G8*101.971/176.71/0.83,2) | O8: =ROUND(G8/17671*1000.2,2) | P8: =ODOO!I8 | Q8: =ODOO!H8
A9: =A8+1 | B9: =ODOO!H9 | C9: 4 | D9: =ODOO!P9 | E9: =ODOO!A9 | F9: =ODOO!G9 | G9: =ROUND( IF(AND(P9="7", OR(ODOO!F9="Class B-1 FA", ODOO!F9="Class B-1 NFA")), RAND()*(480-420)+420, IF(AND(P9="28", OR(ODOO!F9="Class B-1 FA", ODOO!F9="Class B-1 NFA")), RAND()*(650-580)+580, IF(AND(P9="7", ODOO!F9="Fc-30 NFA"), RAND()*(480-420)+420, IF(AND(P9="28", ODOO!F9="Fc-30 NFA"), RAND()*(650-580)+580, IF(AND(P9="7", ODOO!F9="Fc-20 NFA"), RAND()*(275-236)+236, IF(AND(P9="28", ODOO!F9="Fc-20 NFA"), RAND()*(490-410)+410, IF(AND(P9="7", ODOO!F9="Fc-35 NFA"), RAND()*(435-393)+393, IF(AND(P9="28", ODOO!F9="Fc-35 NFA"), RAND()*(680-620)+620, IF(AND(P9="7", ODOO!F9="Fc-15 NFA"), RAND()*(200-175)+175, IF(AND(P9="28", ODOO!F9="Fc-15 NFA"), RAND()*(355-305)+305, IF(AND(P9="7", ODOO!F9="K-300 NFA"), RAND()*(324-278)+278, IF(AND(P9="28", ODOO!F9="K-300 NFA"), RAND()*(520-450)+450, IF(AND(P9="7", ODOO!F9="K-300 FA"), RAND()*(324-278)+278, IF(AND(P9="28", ODOO!F9="K-300 FA"), RAND()*(520-450)+450, IF(AND(P9="7", ODOO!F9="K-400 FA"), RAND()*(415-370)+370, IF(AND(P9="28", ODOO!F9="K-400 FA"), RAND()*(655-591)+591, IF(AND(P9="7", ODOO!F9="K-400 NFA"), RAND()*(415-370)+370, IF(AND(P9="28", ODOO!F9="K-400 NFA"), RAND()*(655-591)+591, IF(AND(P9="7", ODOO!F9="Class B-2 FA"), RAND()*(503-448)+448, IF(AND(P9="28", ODOO!F9="Class B-2 FA"), RAND()*(695-622)+622, IF(AND(P9="7", ODOO!F9="Fc-10 NFA"), RAND()*(155-123)+123, IF(AND(P9="28", ODOO!F9="Fc-10 NFA"), RAND()*(230-200)+200, IF(AND(P9="7", ODOO!F9="Class E-1 NFA"), RAND()*(155-123)+123, IF(AND(P9="28", ODOO!F9="Class E-1 NFA"), RAND()*(230-200)+200, IF(AND(P9="7", ODOO!F9="Class E-1 FA"), RAND()*(155-123)+123, IF(AND(P9="28", ODOO!F9="Class E-1 FA"), RAND()*(230-200)+200, IF(AND(P9="7", ODOO!F9="K-175 NFA"), RAND()*(195-165)+165, IF(AND(P9="28", ODOO!F9="K-175 NFA"), RAND()*(320-270)+270, IF(AND(P9="7", ODOO!F9="K-125 NFA"), RAND()*(155-123)+123, IF(AND(P9="28", ODOO!F9="K-125 NFA"), RAND()*(230-200)+200, IF(AND(P9="7", ODOO!F9="B0-1 NFA"), RAND()*(155-123)+123, IF(AND(P9="28", ODOO!F9="B0-1 NFA"), RAND()*(190-177)+177, IF(AND(P9="7", ODOO!F9="Class C-1 NFA"), RAND()*(275-245)+245, IF(AND(P9="28", ODOO!F9="Class C-1 NFA"), RAND()*(460-407)+407, IF(AND(P9="7", ODOO!F9="K-100 NFA"), RAND()*(115-93)+93, IF(AND(P9="28", ODOO!F9="K-100 NFA"), RAND()*(200-146)+146, IF(AND(P9="7", ODOO!F9="K-100 FA"), RAND()*(115-93)+93, IF(AND(P9="28", ODOO!F9="K-100 FA"), RAND()*(200-146)+146, IF(AND(P9="7", ODOO!F9="K-150 NFA"), RAND()*(150-138)+138, IF(AND(P9="28", ODOO!F9="K-150 NFA"), RAND()*(265-220)+220, IF(AND(P9="7", ODOO!F9="K-150 FA"), RAND()*(150-138)+138, IF(AND(P9="28", ODOO!F9="K-150 FA"), RAND()*(265-220)+220, IF(AND(P9="7", ODOO!F9="K-225 NFA"), RAND()*(240-213)+213, IF(AND(P9="28", ODOO!F9="K-225 NFA"), RAND()*(390-348)+348, IF(AND(P9="7", ODOO!F9="K-225 FA"), RAND()*(240-213)+213, IF(AND(P9="28", ODOO!F9="K-225 FA"), RAND()*(390-348)+348, IF(AND(P9="7", ODOO!F9="K-250 NFA"), RAND()*(275-235)+235, IF(AND(P9="28", ODOO!F9="K-250 NFA"), RAND()*(440-400)+400, IF(AND(P9="7", ODOO!F9="K-250 FA"), RAND()*(275-235)+235, IF(AND(P9="28", ODOO!F9="K-250 FA"), RAND()*(440-400)+400, IF(AND(P9="7", ODOO!F9="K-350 NFA"), RAND()*(390-345)+345, IF(AND(P9="28", ODOO!F9="K-350 NFA"), RAND()*(570-520)+520, IF(AND(P9="7", ODOO!F9="K-350 FA"), RAND()*(390-345)+345, IF(AND(P9="28", ODOO!F9="K-350 FA"), RAND()*(570-520)+520, IF(AND(P9="7", ODOO!F9="K-450 FA"), RAND()*(480-420)+420, IF(AND(P9="28", ODOO!F9="K-450 FA"), RAND()*(730-648)+648, IF(AND(P9="7", ODOO!F9="K-450 NFA"), RAND()*(480-420)+420, IF(AND(P9="28", ODOO!F9="K-450 NFA"), RAND()*(730-648)+648, IF(AND(P9="7", ODOO!F9="K-500 FA"), RAND()*(530-466)+466, IF(AND(P9="28", ODOO!F9="K-500 FA"), RAND()*(800-718)+718, IF(AND(P9="7", ODOO!F9="K-500 NFA"), RAND()*(530-466)+466, IF(AND(P9="28", ODOO!F9="K-500 NFA"), RAND()*(800-718)+718, "0")))))))))))))))))))))))))))))))))))))))))))))))))))))))))))))), 2) | H9: =ROUND(RAND()*(12.56-12)+12.1,2) | I9: =CHOOSE(RANDBETWEEN(1,5), "A", "B", "C", "D", "E") | J9: B | K9: =bjdt_id!C9 | L9: =ODOO!H9 | M9: =ODOO!J9 | N9: =ROUND(G9*101.971/176.71/0.83,2) | O9: =ROUND(G9/17671*1000.2,2) | P9: =ODOO!I9 | Q9: =ODOO!H9
A10: =A9+1 | B10: =ODOO!H10 | C10: 4 | D10: =ODOO!P10 | E10: =ODOO!A10 | F10: =ODOO!G10 | G10: =ROUND( IF(AND(P10="7", OR(ODOO!F10="Class B-1 FA", ODOO!F10="Class B-1 NFA")), RAND()*(480-420)+420, IF(AND(P10="28", OR(ODOO!F10="Class B-1 FA", ODOO!F10="Class B-1 NFA")), RAND()*(650-580)+580, IF(AND(P10="7", ODOO!F10="Fc-30 NFA"), RAND()*(480-420)+420, IF(AND(P10="28", ODOO!F10="Fc-30 NFA"), RAND()*(650-580)+580, IF(AND(P10="7", ODOO!F10="Fc-20 NFA"), RAND()*(275-236)+236, IF(AND(P10="28", ODOO!F10="Fc-20 NFA"), RAND()*(490-410)+410, IF(AND(P10="7", ODOO!F10="Fc-35 NFA"), RAND()*(435-393)+393, IF(AND(P10="28", ODOO!F10="Fc-35 NFA"), RAND()*(680-620)+620, IF(AND(P10="7", ODOO!F10="Fc-15 NFA"), RAND()*(200-175)+175, IF(AND(P10="28", ODOO!F10="Fc-15 NFA"), RAND()*(355-305)+305, IF(AND(P10="7", ODOO!F10="K-300 NFA"), RAND()*(324-278)+278, IF(AND(P10="28", ODOO!F10="K-300 NFA"), RAND()*(520-450)+450, IF(AND(P10="7", ODOO!F10="K-300 FA"), RAND()*(324-278)+278, IF(AND(P10="28", ODOO!F10="K-300 FA"), RAND()*(520-450)+450, IF(AND(P10="7", ODOO!F10="K-400 FA"), RAND()*(415-370)+370, IF(AND(P10="28", ODOO!F10="K-400 FA"), RAND()*(655-591)+591, IF(AND(P10="7", ODOO!F10="K-400 NFA"), RAND()*(415-370)+370, IF(AND(P10="28", ODOO!F10="K-400 NFA"), RAND()*(655-591)+591, IF(AND(P10="7", ODOO!F10="Class B-2 FA"), RAND()*(503-448)+448, IF(AND(P10="28", ODOO!F10="Class B-2 FA"), RAND()*(695-622)+622, IF(AND(P10="7", ODOO!F10="Fc-10 NFA"), RAND()*(155-123)+123, IF(AND(P10="28", ODOO!F10="Fc-10 NFA"), RAND()*(230-200)+200, IF(AND(P10="7", ODOO!F10="Class E-1 NFA"), RAND()*(155-123)+123, IF(AND(P10="28", ODOO!F10="Class E-1 NFA"), RAND()*(230-200)+200, IF(AND(P10="7", ODOO!F10="Class E-1 FA"), RAND()*(155-123)+123, IF(AND(P10="28", ODOO!F10="Class E-1 FA"), RAND()*(230-200)+200, IF(AND(P10="7", ODOO!F10="K-175 NFA"), RAND()*(195-165)+165, IF(AND(P10="28", ODOO!F10="K-175 NFA"), RAND()*(320-270)+270, IF(AND(P10="7", ODOO!F10="K-125 NFA"), RAND()*(155-123)+123, IF(AND(P10="28", ODOO!F10="K-125 NFA"), RAND()*(230-200)+200, IF(AND(P10="7", ODOO!F10="B0-1 NFA"), RAND()*(155-123)+123, IF(AND(P10="28", ODOO!F10="B0-1 NFA"), RAND()*(190-177)+177, IF(AND(P10="7", ODOO!F10="Class C-1 NFA"), RAND()*(275-245)+245, IF(AND(P10="28", ODOO!F10="Class C-1 NFA"), RAND()*(460-407)+407, IF(AND(P10="7", ODOO!F10="K-100 NFA"), RAND()*(115-93)+93, IF(AND(P10="28", ODOO!F10="K-100 NFA"), RAND()*(200-146)+146, IF(AND(P10="7", ODOO!F10="K-100 FA"), RAND()*(115-93)+93, IF(AND(P10="28", ODOO!F10="K-100 FA"), RAND()*(200-146)+146, IF(AND(P10="7", ODOO!F10="K-150 NFA"), RAND()*(150-138)+138, IF(AND(P10="28", ODOO!F10="K-150 NFA"), RAND()*(265-220)+220, IF(AND(P10="7", ODOO!F10="K-150 FA"), RAND()*(150-138)+138, IF(AND(P10="28", ODOO!F10="K-150 FA"), RAND()*(265-220)+220, IF(AND(P10="7", ODOO!F10="K-225 NFA"), RAND()*(240-213)+213, IF(AND(P10="28", ODOO!F10="K-225 NFA"), RAND()*(390-348)+348, IF(AND(P10="7", ODOO!F10="K-225 FA"), RAND()*(240-213)+213, IF(AND(P10="28", ODOO!F10="K-225 FA"), RAND()*(390-348)+348, IF(AND(P10="7", ODOO!F10="K-250 NFA"), RAND()*(275-235)+235, IF(AND(P10="28", ODOO!F10="K-250 NFA"), RAND()*(440-400)+400, IF(AND(P10="7", ODOO!F10="K-250 FA"), RAND()*(275-235)+235, IF(AND(P10="28", ODOO!F10="K-250 FA"), RAND()*(440-400)+400, IF(AND(P10="7", ODOO!F10="K-350 NFA"), RAND()*(390-345)+345, IF(AND(P10="28", ODOO!F10="K-350 NFA"), RAND()*(570-520)+520, IF(AND(P10="7", ODOO!F10="K-350 FA"), RAND()*(390-345)+345, IF(AND(P10="28", ODOO!F10="K-350 FA"), RAND()*(570-520)+520, IF(AND(P10="7", ODOO!F10="K-450 FA"), RAND()*(480-420)+420, IF(AND(P10="28", ODOO!F10="K-450 FA"), RAND()*(730-648)+648, IF(AND(P10="7", ODOO!F10="K-450 NFA"), RAND()*(480-420)+420, IF(AND(P10="28", ODOO!F10="K-450 NFA"), RAND()*(730-648)+648, IF(AND(P10="7", ODOO!F10="K-500 FA"), RAND()*(530-466)+466, IF(AND(P10="28", ODOO!F10="K-500 FA"), RAND()*(800-718)+718, IF(AND(P10="7", ODOO!F10="K-500 NFA"), RAND()*(530-466)+466, IF(AND(P10="28", ODOO!F10="K-500 NFA"), RAND()*(800-718)+718, "0")))))))))))))))))))))))))))))))))))))))))))))))))))))))))))))), 2) | H10: =ROUND(RAND()*(12.56-12)+12.1,2) | I10: =CHOOSE(RANDBETWEEN(1,5), "A", "B", "C", "D", "E") | J10: B | K10: =bjdt_id!C10 | L10: =ODOO!H10 | M10: =ODOO!J10 | N10: =ROUND(G10*101.971/176.71/0.83,2) | O10: =ROUND(G10/17671*1000.2,2) | P10: =ODOO!I10 | Q10: =ODOO!H10
A11: =A10+1 | B11: =ODOO!H11 | C11: 4 | D11: =ODOO!P11 | E11: =ODOO!A11 | F11: =ODOO!G11 | G11: =ROUND( IF(AND(P11="7", OR(ODOO!F11="Class B-1 FA", ODOO!F11="Class B-1 NFA")), RAND()*(480-420)+420, IF(AND(P11="28", OR(ODOO!F11="Class B-1 FA", ODOO!F11="Class B-1 NFA")), RAND()*(650-580)+580, IF(AND(P11="7", ODOO!F11="Fc-30 NFA"), RAND()*(480-420)+420, IF(AND(P11="28", ODOO!F11="Fc-30 NFA"), RAND()*(650-580)+580, IF(AND(P11="7", ODOO!F11="Fc-20 NFA"), RAND()*(275-236)+236, IF(AND(P11="28", ODOO!F11="Fc-20 NFA"), RAND()*(490-410)+410, IF(AND(P11="7", ODOO!F11="Fc-35 NFA"), RAND()*(435-393)+393, IF(AND(P11="28", ODOO!F11="Fc-35 NFA"), RAND()*(680-620)+620, IF(AND(P11="7", ODOO!F11="Fc-15 NFA"), RAND()*(200-175)+175, IF(AND(P11="28", ODOO!F11="Fc-15 NFA"), RAND()*(355-305)+305, IF(AND(P11="7", ODOO!F11="K-300 NFA"), RAND()*(324-278)+278, IF(AND(P11="28", ODOO!F11="K-300 NFA"), RAND()*(520-450)+450, IF(AND(P11="7", ODOO!F11="K-300 FA"), RAND()*(324-278)+278, IF(AND(P11="28", ODOO!F11="K-300 FA"), RAND()*(520-450)+450, IF(AND(P11="7", ODOO!F11="K-400 FA"), RAND()*(415-370)+370, IF(AND(P11="28", ODOO!F11="K-400 FA"), RAND()*(655-591)+591, IF(AND(P11="7", ODOO!F11="K-400 NFA"), RAND()*(415-370)+370, IF(AND(P11="28", ODOO!F11="K-400 NFA"), RAND()*(655-591)+591, IF(AND(P11="7", ODOO!F11="Class B-2 FA"), RAND()*(503-448)+448, IF(AND(P11="28", ODOO!F11="Class B-2 FA"), RAND()*(695-622)+622, IF(AND(P11="7", ODOO!F11="Fc-10 NFA"), RAND()*(155-123)+123, IF(AND(P11="28", ODOO!F11="Fc-10 NFA"), RAND()*(230-200)+200, IF(AND(P11="7", ODOO!F11="Class E-1 NFA"), RAND()*(155-123)+123, IF(AND(P11="28", ODOO!F11="Class E-1 NFA"), RAND()*(230-200)+200, IF(AND(P11="7", ODOO!F11="Class E-1 FA"), RAND()*(155-123)+123, IF(AND(P11="28", ODOO!F11="Class E-1 FA"), RAND()*(230-200)+200, IF(AND(P11="7", ODOO!F11="K-175 NFA"), RAND()*(195-165)+165, IF(AND(P11="28", ODOO!F11="K-175 NFA"), RAND()*(320-270)+270, IF(AND(P11="7", ODOO!F11="K-125 NFA"), RAND()*(155-123)+123, IF(AND(P11="28", ODOO!F11="K-125 NFA"), RAND()*(230-200)+200, IF(AND(P11="7", ODOO!F11="B0-1 NFA"), RAND()*(155-123)+123, IF(AND(P11="28", ODOO!F11="B0-1 NFA"), RAND()*(190-177)+177, IF(AND(P11="7", ODOO!F11="Class C-1 NFA"), RAND()*(275-245)+245, IF(AND(P11="28", ODOO!F11="Class C-1 NFA"), RAND()*(460-407)+407, IF(AND(P11="7", ODOO!F11="K-100 NFA"), RAND()*(115-93)+93, IF(AND(P11="28", ODOO!F11="K-100 NFA"), RAND()*(200-146)+146, IF(AND(P11="7", ODOO!F11="K-100 FA"), RAND()*(115-93)+93, IF(AND(P11="28", ODOO!F11="K-100 FA"), RAND()*(200-146)+146, IF(AND(P11="7", ODOO!F11="K-150 NFA"), RAND()*(150-138)+138, IF(AND(P11="28", ODOO!F11="K-150 NFA"), RAND()*(265-220)+220, IF(AND(P11="7", ODOO!F11="K-150 FA"), RAND()*(150-138)+138, IF(AND(P11="28", ODOO!F11="K-150 FA"), RAND()*(265-220)+220, IF(AND(P11="7", ODOO!F11="K-225 NFA"), RAND()*(240-213)+213, IF(AND(P11="28", ODOO!F11="K-225 NFA"), RAND()*(390-348)+348, IF(AND(P11="7", ODOO!F11="K-225 FA"), RAND()*(240-213)+213, IF(AND(P11="28", ODOO!F11="K-225 FA"), RAND()*(390-348)+348, IF(AND(P11="7", ODOO!F11="K-250 NFA"), RAND()*(275-235)+235, IF(AND(P11="28", ODOO!F11="K-250 NFA"), RAND()*(440-400)+400, IF(AND(P11="7", ODOO!F11="K-250 FA"), RAND()*(275-235)+235, IF(AND(P11="28", ODOO!F11="K-250 FA"), RAND()*(440-400)+400, IF(AND(P11="7", ODOO!F11="K-350 NFA"), RAND()*(390-345)+345, IF(AND(P11="28", ODOO!F11="K-350 NFA"), RAND()*(570-520)+520, IF(AND(P11="7", ODOO!F11="K-350 FA"), RAND()*(390-345)+345, IF(AND(P11="28", ODOO!F11="K-350 FA"), RAND()*(570-520)+520, IF(AND(P11="7", ODOO!F11="K-450 FA"), RAND()*(480-420)+420, IF(AND(P11="28", ODOO!F11="K-450 FA"), RAND()*(730-648)+648, IF(AND(P11="7", ODOO!F11="K-450 NFA"), RAND()*(480-420)+420, IF(AND(P11="28", ODOO!F11="K-450 NFA"), RAND()*(730-648)+648, IF(AND(P11="7", ODOO!F11="K-500 FA"), RAND()*(530-466)+466, IF(AND(P11="28", ODOO!F11="K-500 FA"), RAND()*(800-718)+718, IF(AND(P11="7", ODOO!F11="K-500 NFA"), RAND()*(530-466)+466, IF(AND(P11="28", ODOO!F11="K-500 NFA"), RAND()*(800-718)+718, "0")))))))))))))))))))))))))))))))))))))))))))))))))))))))))))))), 2) | H11: =ROUND(RAND()*(12.56-12)+12.1,2) | I11: =CHOOSE(RANDBETWEEN(1,5), "A", "B", "C", "D", "E") | J11: B | K11: =bjdt_id!C11 | L11: =ODOO!H11 | M11: =ODOO!J11 | N11: =ROUND(G11*101.971/176.71/0.83,2) | O11: =ROUND(G11/17671*1000.2,2) | P11: =ODOO!I11 | Q11: =ODOO!H11
A12: =A11+1 | B12: =ODOO!H12 | C12: 4 | D12: =ODOO!P12 | E12: =ODOO!A12 | F12: =ODOO!G12 | G12: =ROUND( IF(AND(P12="7", OR(ODOO!F12="Class B-1 FA", ODOO!F12="Class B-1 NFA")), RAND()*(480-420)+420, IF(AND(P12="28", OR(ODOO!F12="Class B-1 FA", ODOO!F12="Class B-1 NFA")), RAND()*(650-580)+580, IF(AND(P12="7", ODOO!F12="Fc-30 NFA"), RAND()*(480-420)+420, IF(AND(P12="28", ODOO!F12="Fc-30 NFA"), RAND()*(650-580)+580, IF(AND(P12="7", ODOO!F12="Fc-20 NFA"), RAND()*(275-236)+236, IF(AND(P12="28", ODOO!F12="Fc-20 NFA"), RAND()*(490-410)+410, IF(AND(P12="7", ODOO!F12="Fc-35 NFA"), RAND()*(435-393)+393, IF(AND(P12="28", ODOO!F12="Fc-35 NFA"), RAND()*(680-620)+620, IF(AND(P12="7", ODOO!F12="Fc-15 NFA"), RAND()*(200-175)+175, IF(AND(P12="28", ODOO!F12="Fc-15 NFA"), RAND()*(355-305)+305, IF(AND(P12="7", ODOO!F12="K-300 NFA"), RAND()*(324-278)+278, IF(AND(P12="28", ODOO!F12="K-300 NFA"), RAND()*(520-450)+450, IF(AND(P12="7", ODOO!F12="K-300 FA"), RAND()*(324-278)+278, IF(AND(P12="28", ODOO!F12="K-300 FA"), RAND()*(520-450)+450, IF(AND(P12="7", ODOO!F12="K-400 FA"), RAND()*(415-370)+370, IF(AND(P12="28", ODOO!F12="K-400 FA"), RAND()*(655-591)+591, IF(AND(P12="7", ODOO!F12="K-400 NFA"), RAND()*(415-370)+370, IF(AND(P12="28", ODOO!F12="K-400 NFA"), RAND()*(655-591)+591, IF(AND(P12="7", ODOO!F12="Class B-2 FA"), RAND()*(503-448)+448, IF(AND(P12="28", ODOO!F12="Class B-2 FA"), RAND()*(695-622)+622, IF(AND(P12="7", ODOO!F12="Fc-10 NFA"), RAND()*(155-123)+123, IF(AND(P12="28", ODOO!F12="Fc-10 NFA"), RAND()*(230-200)+200, IF(AND(P12="7", ODOO!F12="Class E-1 NFA"), RAND()*(155-123)+123, IF(AND(P12="28", ODOO!F12="Class E-1 NFA"), RAND()*(230-200)+200, IF(AND(P12="7", ODOO!F12="Class E-1 FA"), RAND()*(155-123)+123, IF(AND(P12="28", ODOO!F12="Class E-1 FA"), RAND()*(230-200)+200, IF(AND(P12="7", ODOO!F12="K-175 NFA"), RAND()*(195-165)+165, IF(AND(P12="28", ODOO!F12="K-175 NFA"), RAND()*(320-270)+270, IF(AND(P12="7", ODOO!F12="K-125 NFA"), RAND()*(155-123)+123, IF(AND(P12="28", ODOO!F12="K-125 NFA"), RAND()*(230-200)+200, IF(AND(P12="7", ODOO!F12="B0-1 NFA"), RAND()*(155-123)+123, IF(AND(P12="28", ODOO!F12="B0-1 NFA"), RAND()*(190-177)+177, IF(AND(P12="7", ODOO!F12="Class C-1 NFA"), RAND()*(275-245)+245, IF(AND(P12="28", ODOO!F12="Class C-1 NFA"), RAND()*(460-407)+407, IF(AND(P12="7", ODOO!F12="K-100 NFA"), RAND()*(115-93)+93, IF(AND(P12="28", ODOO!F12="K-100 NFA"), RAND()*(200-146)+146, IF(AND(P12="7", ODOO!F12="K-100 FA"), RAND()*(115-93)+93, IF(AND(P12="28", ODOO!F12="K-100 FA"), RAND()*(200-146)+146, IF(AND(P12="7", ODOO!F12="K-150 NFA"), RAND()*(150-138)+138, IF(AND(P12="28", ODOO!F12="K-150 NFA"), RAND()*(265-220)+220, IF(AND(P12="7", ODOO!F12="K-150 FA"), RAND()*(150-138)+138, IF(AND(P12="28", ODOO!F12="K-150 FA"), RAND()*(265-220)+220, IF(AND(P12="7", ODOO!F12="K-225 NFA"), RAND()*(240-213)+213, IF(AND(P12="28", ODOO!F12="K-225 NFA"), RAND()*(390-348)+348, IF(AND(P12="7", ODOO!F12="K-225 FA"), RAND()*(240-213)+213, IF(AND(P12="28", ODOO!F12="K-225 FA"), RAND()*(390-348)+348, IF(AND(P12="7", ODOO!F12="K-250 NFA"), RAND()*(275-235)+235, IF(AND(P12="28", ODOO!F12="K-250 NFA"), RAND()*(440-400)+400, IF(AND(P12="7", ODOO!F12="K-250 FA"), RAND()*(275-235)+235, IF(AND(P12="28", ODOO!F12="K-250 FA"), RAND()*(440-400)+400, IF(AND(P12="7", ODOO!F12="K-350 NFA"), RAND()*(390-345)+345, IF(AND(P12="28", ODOO!F12="K-350 NFA"), RAND()*(570-520)+520, IF(AND(P12="7", ODOO!F12="K-350 FA"), RAND()*(390-345)+345, IF(AND(P12="28", ODOO!F12="K-350 FA"), RAND()*(570-520)+520, IF(AND(P12="7", ODOO!F12="K-450 FA"), RAND()*(480-420)+420, IF(AND(P12="28", ODOO!F12="K-450 FA"), RAND()*(730-648)+648, IF(AND(P12="7", ODOO!F12="K-450 NFA"), RAND()*(480-420)+420, IF(AND(P12="28", ODOO!F12="K-450 NFA"), RAND()*(730-648)+648, IF(AND(P12="7", ODOO!F12="K-500 FA"), RAND()*(530-466)+466, IF(AND(P12="28", ODOO!F12="K-500 FA"), RAND()*(800-718)+718, IF(AND(P12="7", ODOO!F12="K-500 NFA"), RAND()*(530-466)+466, IF(AND(P12="28", ODOO!F12="K-500 NFA"), RAND()*(800-718)+718, "0")))))))))))))))))))))))))))))))))))))))))))))))))))))))))))))), 2) | H12: =ROUND(RAND()*(12.56-12)+12.1,2) | I12: =CHOOSE(RANDBETWEEN(1,5), "A", "B", "C", "D", "E") | J12: B | K12: =bjdt_id!C12 | L12: =ODOO!H12 | M12: =ODOO!J12 | N12: =ROUND(G12*101.971/176.71/0.83,2) | O12: =ROUND(G12/17671*1000.2,2) | P12: =ODOO!I12 | Q12: =ODOO!H12
A13: =A12+1 | B13: =ODOO!H13 | C13: 4 | D13: =ODOO!P13 | E13: =ODOO!A13 | F13: =ODOO!G13 | G13: =ROUND( IF(AND(P13="7", OR(ODOO!F13="Class B-1 FA", ODOO!F13="Class B-1 NFA")), RAND()*(480-420)+420, IF(AND(P13="28", OR(ODOO!F13="Class B-1 FA", ODOO!F13="Class B-1 NFA")), RAND()*(650-580)+580, IF(AND(P13="7", ODOO!F13="Fc-30 NFA"), RAND()*(480-420)+420, IF(AND(P13="28", ODOO!F13="Fc-30 NFA"), RAND()*(650-580)+580, IF(AND(P13="7", ODOO!F13="Fc-20 NFA"), RAND()*(275-236)+236, IF(AND(P13="28", ODOO!F13="Fc-20 NFA"), RAND()*(490-410)+410, IF(AND(P13="7", ODOO!F13="Fc-35 NFA"), RAND()*(435-393)+393, IF(AND(P13="28", ODOO!F13="Fc-35 NFA"), RAND()*(680-620)+620, IF(AND(P13="7", ODOO!F13="Fc-15 NFA"), RAND()*(200-175)+175, IF(AND(P13="28", ODOO!F13="Fc-15 NFA"), RAND()*(355-305)+305, IF(AND(P13="7", ODOO!F13="K-300 NFA"), RAND()*(324-278)+278, IF(AND(P13="28", ODOO!F13="K-300 NFA"), RAND()*(520-450)+450, IF(AND(P13="7", ODOO!F13="K-300 FA"), RAND()*(324-278)+278, IF(AND(P13="28", ODOO!F13="K-300 FA"), RAND()*(520-450)+450, IF(AND(P13="7", ODOO!F13="K-400 FA"), RAND()*(415-370)+370, IF(AND(P13="28", ODOO!F13="K-400 FA"), RAND()*(655-591)+591, IF(AND(P13="7", ODOO!F13="K-400 NFA"), RAND()*(415-370)+370, IF(AND(P13="28", ODOO!F13="K-400 NFA"), RAND()*(655-591)+591, IF(AND(P13="7", ODOO!F13="Class B-2 FA"), RAND()*(503-448)+448, IF(AND(P13="28", ODOO!F13="Class B-2 FA"), RAND()*(695-622)+622, IF(AND(P13="7", ODOO!F13="Fc-10 NFA"), RAND()*(155-123)+123, IF(AND(P13="28", ODOO!F13="Fc-10 NFA"), RAND()*(230-200)+200, IF(AND(P13="7", ODOO!F13="Class E-1 NFA"), RAND()*(155-123)+123, IF(AND(P13="28", ODOO!F13="Class E-1 NFA"), RAND()*(230-200)+200, IF(AND(P13="7", ODOO!F13="Class E-1 FA"), RAND()*(155-123)+123, IF(AND(P13="28", ODOO!F13="Class E-1 FA"), RAND()*(230-200)+200, IF(AND(P13="7", ODOO!F13="K-175 NFA"), RAND()*(195-165)+165, IF(AND(P13="28", ODOO!F13="K-175 NFA"), RAND()*(320-270)+270, IF(AND(P13="7", ODOO!F13="K-125 NFA"), RAND()*(155-123)+123, IF(AND(P13="28", ODOO!F13="K-125 NFA"), RAND()*(230-200)+200, IF(AND(P13="7", ODOO!F13="B0-1 NFA"), RAND()*(155-123)+123, IF(AND(P13="28", ODOO!F13="B0-1 NFA"), RAND()*(190-177)+177, IF(AND(P13="7", ODOO!F13="Class C-1 NFA"), RAND()*(275-245)+245, IF(AND(P13="28", ODOO!F13="Class C-1 NFA"), RAND()*(460-407)+407, IF(AND(P13="7", ODOO!F13="K-100 NFA"), RAND()*(115-93)+93, IF(AND(P13="28", ODOO!F13="K-100 NFA"), RAND()*(200-146)+146, IF(AND(P13="7", ODOO!F13="K-100 FA"), RAND()*(115-93)+93, IF(AND(P13="28", ODOO!F13="K-100 FA"), RAND()*(200-146)+146, IF(AND(P13="7", ODOO!F13="K-150 NFA"), RAND()*(150-138)+138, IF(AND(P13="28", ODOO!F13="K-150 NFA"), RAND()*(265-220)+220, IF(AND(P13="7", ODOO!F13="K-150 FA"), RAND()*(150-138)+138, IF(AND(P13="28", ODOO!F13="K-150 FA"), RAND()*(265-220)+220, IF(AND(P13="7", ODOO!F13="K-225 NFA"), RAND()*(240-213)+213, IF(AND(P13="28", ODOO!F13="K-225 NFA"), RAND()*(390-348)+348, IF(AND(P13="7", ODOO!F13="K-225 FA"), RAND()*(240-213)+213, IF(AND(P13="28", ODOO!F13="K-225 FA"), RAND()*(390-348)+348, IF(AND(P13="7", ODOO!F13="K-250 NFA"), RAND()*(275-235)+235, IF(AND(P13="28", ODOO!F13="K-250 NFA"), RAND()*(440-400)+400, IF(AND(P13="7", ODOO!F13="K-250 FA"), RAND()*(275-235)+235, IF(AND(P13="28", ODOO!F13="K-250 FA"), RAND()*(440-400)+400, IF(AND(P13="7", ODOO!F13="K-350 NFA"), RAND()*(390-345)+345, IF(AND(P13="28", ODOO!F13="K-350 NFA"), RAND()*(570-520)+520, IF(AND(P13="7", ODOO!F13="K-350 FA"), RAND()*(390-345)+345, IF(AND(P13="28", ODOO!F13="K-350 FA"), RAND()*(570-520)+520, IF(AND(P13="7", ODOO!F13="K-450 FA"), RAND()*(480-420)+420, IF(AND(P13="28", ODOO!F13="K-450 FA"), RAND()*(730-648)+648, IF(AND(P13="7", ODOO!F13="K-450 NFA"), RAND()*(480-420)+420, IF(AND(P13="28", ODOO!F13="K-450 NFA"), RAND()*(730-648)+648, IF(AND(P13="7", ODOO!F13="K-500 FA"), RAND()*(530-466)+466, IF(AND(P13="28", ODOO!F13="K-500 FA"), RAND()*(800-718)+718, IF(AND(P13="7", ODOO!F13="K-500 NFA"), RAND()*(530-466)+466, IF(AND(P13="28", ODOO!F13="K-500 NFA"), RAND()*(800-718)+718, "0")))))))))))))))))))))))))))))))))))))))))))))))))))))))))))))), 2) | H13: =ROUND(RAND()*(12.56-12)+12.1,2) | I13: =CHOOSE(RANDBETWEEN(1,5), "A", "B", "C", "D", "E") | J13: B | K13: =bjdt_id!C13 | L13: =ODOO!H13 | M13: =ODOO!J13 | N13: =ROUND(G13*101.971/176.71/0.83,2) | O13: =ROUND(G13/17671*1000.2,2) | P13: =ODOO!I13 | Q13: =ODOO!H13
A14: =A13+1 | B14: =ODOO!H14 | C14: 4 | D14: =ODOO!P14 | E14: =ODOO!A14 | F14: =ODOO!G14 | G14: =ROUND( IF(AND(P14="7", OR(ODOO!F14="Class B-1 FA", ODOO!F14="Class B-1 NFA")), RAND()*(480-420)+420, IF(AND(P14="28", OR(ODOO!F14="Class B-1 FA", ODOO!F14="Class B-1 NFA")), RAND()*(650-580)+580, IF(AND(P14="7", ODOO!F14="Fc-30 NFA"), RAND()*(480-420)+420, IF(AND(P14="28", ODOO!F14="Fc-30 NFA"), RAND()*(650-580)+580, IF(AND(P14="7", ODOO!F14="Fc-20 NFA"), RAND()*(275-236)+236, IF(AND(P14="28", ODOO!F14="Fc-20 NFA"), RAND()*(490-410)+410, IF(AND(P14="7", ODOO!F14="Fc-35 NFA"), RAND()*(435-393)+393, IF(AND(P14="28", ODOO!F14="Fc-35 NFA"), RAND()*(680-620)+620, IF(AND(P14="7", ODOO!F14="Fc-15 NFA"), RAND()*(200-175)+175, IF(AND(P14="28", ODOO!F14="Fc-15 NFA"), RAND()*(355-305)+305, IF(AND(P14="7", ODOO!F14="K-300 NFA"), RAND()*(324-278)+278, IF(AND(P14="28", ODOO!F14="K-300 NFA"), RAND()*(520-450)+450, IF(AND(P14="7", ODOO!F14="K-300 FA"), RAND()*(324-278)+278, IF(AND(P14="28", ODOO!F14="K-300 FA"), RAND()*(520-450)+450, IF(AND(P14="7", ODOO!F14="K-400 FA"), RAND()*(415-370)+370, IF(AND(P14="28", ODOO!F14="K-400 FA"), RAND()*(655-591)+591, IF(AND(P14="7", ODOO!F14="K-400 NFA"), RAND()*(415-370)+370, IF(AND(P14="28", ODOO!F14="K-400 NFA"), RAND()*(655-591)+591, IF(AND(P14="7", ODOO!F14="Class B-2 FA"), RAND()*(503-448)+448, IF(AND(P14="28", ODOO!F14="Class B-2 FA"), RAND()*(695-622)+622, IF(AND(P14="7", ODOO!F14="Fc-10 NFA"), RAND()*(155-123)+123, IF(AND(P14="28", ODOO!F14="Fc-10 NFA"), RAND()*(230-200)+200, IF(AND(P14="7", ODOO!F14="Class E-1 NFA"), RAND()*(155-123)+123, IF(AND(P14="28", ODOO!F14="Class E-1 NFA"), RAND()*(230-200)+200, IF(AND(P14="7", ODOO!F14="Class E-1 FA"), RAND()*(155-123)+123, IF(AND(P14="28", ODOO!F14="Class E-1 FA"), RAND()*(230-200)+200, IF(AND(P14="7", ODOO!F14="K-175 NFA"), RAND()*(195-165)+165, IF(AND(P14="28", ODOO!F14="K-175 NFA"), RAND()*(320-270)+270, IF(AND(P14="7", ODOO!F14="K-125 NFA"), RAND()*(155-123)+123, IF(AND(P14="28", ODOO!F14="K-125 NFA"), RAND()*(230-200)+200, IF(AND(P14="7", ODOO!F14="B0-1 NFA"), RAND()*(155-123)+123, IF(AND(P14="28", ODOO!F14="B0-1 NFA"), RAND()*(190-177)+177, IF(AND(P14="7", ODOO!F14="Class C-1 NFA"), RAND()*(275-245)+245, IF(AND(P14="28", ODOO!F14="Class C-1 NFA"), RAND()*(460-407)+407, IF(AND(P14="7", ODOO!F14="K-100 NFA"), RAND()*(115-93)+93, IF(AND(P14="28", ODOO!F14="K-100 NFA"), RAND()*(200-146)+146, IF(AND(P14="7", ODOO!F14="K-100 FA"), RAND()*(115-93)+93, IF(AND(P14="28", ODOO!F14="K-100 FA"), RAND()*(200-146)+146, IF(AND(P14="7", ODOO!F14="K-150 NFA"), RAND()*(150-138)+138, IF(AND(P14="28", ODOO!F14="K-150 NFA"), RAND()*(265-220)+220, IF(AND(P14="7", ODOO!F14="K-150 FA"), RAND()*(150-138)+138, IF(AND(P14="28", ODOO!F14="K-150 FA"), RAND()*(265-220)+220, IF(AND(P14="7", ODOO!F14="K-225 NFA"), RAND()*(240-213)+213, IF(AND(P14="28", ODOO!F14="K-225 NFA"), RAND()*(390-348)+348, IF(AND(P14="7", ODOO!F14="K-225 FA"), RAND()*(240-213)+213, IF(AND(P14="28", ODOO!F14="K-225 FA"), RAND()*(390-348)+348, IF(AND(P14="7", ODOO!F14="K-250 NFA"), RAND()*(275-235)+235, IF(AND(P14="28", ODOO!F14="K-250 NFA"), RAND()*(440-400)+400, IF(AND(P14="7", ODOO!F14="K-250 FA"), RAND()*(275-235)+235, IF(AND(P14="28", ODOO!F14="K-250 FA"), RAND()*(440-400)+400, IF(AND(P14="7", ODOO!F14="K-350 NFA"), RAND()*(390-345)+345, IF(AND(P14="28", ODOO!F14="K-350 NFA"), RAND()*(570-520)+520, IF(AND(P14="7", ODOO!F14="K-350 FA"), RAND()*(390-345)+345, IF(AND(P14="28", ODOO!F14="K-350 FA"), RAND()*(570-520)+520, IF(AND(P14="7", ODOO!F14="K-450 FA"), RAND()*(480-420)+420, IF(AND(P14="28", ODOO!F14="K-450 FA"), RAND()*(730-648)+648, IF(AND(P14="7", ODOO!F14="K-450 NFA"), RAND()*(480-420)+420, IF(AND(P14="28", ODOO!F14="K-450 NFA"), RAND()*(730-648)+648, IF(AND(P14="7", ODOO!F14="K-500 FA"), RAND()*(530-466)+466, IF(AND(P14="28", ODOO!F14="K-500 FA"), RAND()*(800-718)+718, IF(AND(P14="7", ODOO!F14="K-500 NFA"), RAND()*(530-466)+466, IF(AND(P14="28", ODOO!F14="K-500 NFA"), RAND()*(800-718)+718, "0")))))))))))))))))))))))))))))))))))))))))))))))))))))))))))))), 2) | H14: =ROUND(RAND()*(12.56-12)+12.1,2) | I14: =CHOOSE(RANDBETWEEN(1,5), "A", "B", "C", "D", "E") | J14: B | K14: =bjdt_id!C14 | L14: =ODOO!H14 | M14: =ODOO!J14 | N14: =ROUND(G14*101.971/176.71/0.83,2) | O14: =ROUND(G14/17671*1000.2,2) | P14: =ODOO!I14 | Q14: =ODOO!H14
... A600: =A599+1 | B600: =ODOO!H600 | C600: 4 | D600: =ODOO!P600 | E600: =ODOO!A600 | F600: =ODOO!G600 | G600: =ROUND( IF(AND(P600="7", OR(ODOO!F600="Class B-1 FA", ODOO!F600="Class B-1 NFA")), RAND()*(480-420)+420, IF(AND(P600="28", OR(ODOO!F600="Class B-1 FA", ODOO!F600="Class B-1 NFA")), RAND()*(650-580)+580, IF(AND(P600="7", ODOO!F600="Fc-30 NFA"), RAND()*(480-420)+420, IF(AND(P600="28", ODOO!F600="Fc-30 NFA"), RAND()*(650-580)+580, IF(AND(P600="7", ODOO!F600="Fc-20 NFA"), RAND()*(275-236)+236, IF(AND(P600="28", ODOO!F600="Fc-20 NFA"), RAND()*(490-410)+410, IF(AND(P600="7", ODOO!F600="Fc-35 NFA"), RAND()*(435-393)+393, IF(AND(P600="28", ODOO!F600="Fc-35 NFA"), RAND()*(680-620)+620, IF(AND(P600="7", ODOO!F600="Fc-15 NFA"), RAND()*(200-175)+175, IF(AND(P600="28", ODOO!F600="Fc-15 NFA"), RAND()*(355-305)+305, IF(AND(P600="7", ODOO!F600="K-300 NFA"), RAND()*(324-278)+278, IF(AND(P600="28", ODOO!F600="K-300 NFA"), RAND()*(520-450)+450, IF(AND(P600="7", ODOO!F600="K-300 FA"), RAND()*(324-278)+278, IF(AND(P600="28", ODOO!F600="K-300 FA"), RAND()*(520-450)+450, IF(AND(P600="7", ODOO!F600="K-400 FA"), RAND()*(415-370)+370, IF(AND(P600="28", ODOO!F600="K-400 FA"), RAND()*(655-591)+591, IF(AND(P600="7", ODOO!F600="K-400 NFA"), RAND()*(415-370)+370, IF(AND(P600="28", ODOO!F600="K-400 NFA"), RAND()*(655-591)+591, IF(AND(P600="7", ODOO!F600="Class B-2 FA"), RAND()*(503-448)+448, IF(AND(P600="28", ODOO!F600="Class B-2 FA"), RAND()*(695-622)+622, IF(AND(P600="7", ODOO!F600="Fc-10 NFA"), RAND()*(155-123)+123, IF(AND(P600="28", ODOO!F600="Fc-10 NFA"), RAND()*(230-200)+200, IF(AND(P600="7", ODOO!F600="Class E-1 NFA"), RAND()*(155-123)+123, IF(AND(P600="28", ODOO!F600="Class E-1 NFA"), RAND()*(230-200)+200, IF(AND(P600="7", ODOO!F600="Class E-1 FA"), RAND()*(155-123)+123, IF(AND(P600="28", ODOO!F600="Class E-1 FA"), RAND()*(230-200)+200, IF(AND(P600="7", ODOO!F600="K-175 NFA"), RAND()*(195-165)+165, IF(AND(P600="28", ODOO!F600="K-175 NFA"), RAND()*(320-270)+270, IF(AND(P600="7", ODOO!F600="K-125 NFA"), RAND()*(155-123)+123, IF(AND(P600="28", ODOO!F600="K-125 NFA"), RAND()*(230-200)+200, IF(AND(P600="7", ODOO!F600="B0-1 NFA"), RAND()*(155-123)+123, IF(AND(P600="28", ODOO!F600="B0-1 NFA"), RAND()*(190-177)+177, IF(AND(P600="7", ODOO!F600="Class C-1 NFA"), RAND()*(275-245)+245, IF(AND(P600="28", ODOO!F600="Class C-1 NFA"), RAND()*(460-407)+407, IF(AND(P600="7", ODOO!F600="K-100 NFA"), RAND()*(115-93)+93, IF(AND(P600="28", ODOO!F600="K-100 NFA"), RAND()*(200-146)+146, IF(AND(P600="7", ODOO!F600="K-100 FA"), RAND()*(115-93)+93, IF(AND(P600="28", ODOO!F600="K-100 FA"), RAND()*(200-146)+146, IF(AND(P600="7", ODOO!F600="K-150 NFA"), RAND()*(150-138)+138, IF(AND(P600="28", ODOO!F600="K-150 NFA"), RAND()*(265-220)+220, IF(AND(P600="7", ODOO!F600="K-150 FA"), RAND()*(150-138)+138, IF(AND(P600="28", ODOO!F600="K-150 FA"), RAND()*(265-220)+220, IF(AND(P600="7", ODOO!F600="K-225 NFA"), RAND()*(240-213)+213, IF(AND(P600="28", ODOO!F600="K-225 NFA"), RAND()*(390-348)+348, IF(AND(P600="7", ODOO!F600="K-225 FA"), RAND()*(240-213)+213, IF(AND(P600="28", ODOO!F600="K-225 FA"), RAND()*(390-348)+348, IF(AND(P600="7", ODOO!F600="K-250 NFA"), RAND()*(275-235)+235, IF(AND(P600="28", ODOO!F600="K-250 NFA"), RAND()*(440-400)+400, IF(AND(P600="7", ODOO!F600="K-250 FA"), RAND()*(275-235)+235, IF(AND(P600="28", ODOO!F600="K-250 FA"), RAND()*(440-400)+400, IF(AND(P600="7", ODOO!F600="K-350 NFA"), RAND()*(390-345)+345, IF(AND(P600="28", ODOO!F600="K-350 NFA"), RAND()*(570-520)+520, IF(AND(P600="7", ODOO!F600="K-350 FA"), RAND()*(390-345)+345, IF(AND(P600="28", ODOO!F600="K-350 FA"), RAND()*(570-520)+520, IF(AND(P600="7", ODOO!F600="K-450 FA"), RAND()*(480-420)+420, IF(AND(P600="28", ODOO!F600="K-450 FA"), RAND()*(730-648)+648, IF(AND(P600="7", ODOO!F600="K-450 NFA"), RAND()*(480-420)+420, IF(AND(P600="28", ODOO!F600="K-450 NFA"), RAND()*(730-648)+648, IF(AND(P600="7", ODOO!F600="K-500 FA"), RAND()*(530-466)+466, IF(AND(P600="28", ODOO!F600="K-500 FA"), RAND()*(800-718)+718, IF(AND(P600="7", ODOO!F600="K-500 NFA"), RAND()*(530-466)+466, IF(AND(P600="28", ODOO!F600="K-500 NFA"), RAND()*(800-718)+718, "0")))))))))))))))))))))))))))))))))))))))))))))))))))))))))))))), 2) | H600: =ROUND(RAND()*(12.56-12)+12.1,2) | I600: =CHOOSE(RANDBETWEEN(1,5), "A", "B", "C", "D", "E") | J600: B | K600: =bjdt_id!C600 | L600: =ODOO!H600 | M600: =ODOO!J600 | N600: =ROUND(G600*101.971/176.71/0.83,2) | O600: =ROUND(G600/17671*1000.2,2) | P600: =ODOO!I600 | Q600: =ODOO!H600

Sheet ODOO
